<?xml version="1.0" encoding="utf-8" ?>
<!-- =================================================================================== -->
<!-- |    This document was autogenerated by xacro from /home/zhitao/diskE/Project/homework2_summation/hw35_wind_ws/src/wind_generator_description/urdf/wind_generator.xacro | -->
<!-- |    EDITING THIS FILE BY HAND IS NOT RECOMMENDED                                 | -->
<!-- =================================================================================== -->
<robot name="wind_generator_description">
    <link name="wind_generator_base_link">

<inertial>
            <origin rpy="0 0 0" xyz="-7.10843281312989E-05 0.491296848849994 43.6344490261791" />
            <mass value="500408.414798168" />
            <inertia ixx="212632115.533089" ixy="10.9440050203581" ixz="377.864923222369" iyy="212166431.458184" iyz="-5110.69754849432" izz="1134023.34164054" />
        </inertial>

        <visual>
            <origin rpy="0 0 0" xyz="0 0 0" />
            <geometry>
                <mesh filename="/home/byz/WTBinspector_ws/src/fans_model/wind_generator_description/meshes/base_link.STL" />
            </geometry>
            <material name="">
                <color rgba="1 1 1 1" />
            </material>
        </visual>
        <collision>
            <origin rpy="0 0 0" xyz="0 0 0" />
            <geometry>
                <mesh filename="/home/byz/WTBinspector_ws/src/fans_model/wind_generator_description/meshes/base_link.STL" />
            </geometry>
        </collision>
    </link>
    <link name="wind_generator_rotor_link">

<inertial>
            <origin rpy="0 0 0" xyz="-2.75491345601564E-05 -1.39576441191558E-05 1.40740943504022" />
            <mass value="210138.068552735" />
            <inertia ixx="6446030.2620646" ixy="-18.2882221466862" ixz="-6.82734054048524" iyy="6446109.93502176" iyz="5.89207002545299" izz="12749400.3079152" />
        </inertial>

        <visual>
            <origin rpy="0 0 0" xyz="0 0 0" />
            <geometry>
                <mesh filename="/home/byz/WTBinspector_ws/src/fans_model/wind_generator_description/meshes/link1.STL" />
            </geometry>
            <material name="">
                <color rgba="1 1 1 1" />
            </material>
        </visual>
        <collision>
            <origin rpy="0 0 0" xyz="0 0 0" />
            <geometry>
                <mesh filename="/home/byz/WTBinspector_ws/src/fans_model/wind_generator_description/meshes/link1.STL" />
            </geometry>
        </collision>
    </link>
    <joint name="fans_joint" type="revolute">
        <origin rpy="1.5708 -0.064022 0" xyz="0.00010227 -1.9994 82.4" />
        <parent link="wind_generator_base_link" />
        <child link="wind_generator_rotor_link" />
        <axis xyz="0 0 1" />
        <limit effort="1000" lower="-10000" upper="10000" velocity="1.0" />
    </joint>

    <link name="wind_generator_world" />

    <joint name="base_joint" type="fixed">
        <origin rpy="0 0 0" xyz="0 0 0.01" />
        <parent link="wind_generator_world" />
        <child link="wind_generator_base_link" />
        <axis xyz="0 0 0" />
    </joint>

<transmission name="trans_fans_joint">
        <type>transmission_interface/SimpleTransmission</type>
        <joint name="fans_joint">
            <hardwareInterface>hardware_interface/PositionJointInterface</hardwareInterface>
        </joint>
        <actuator name="fans_joint_motor">
            <hardwareInterface>hardware_interface/PositionJointInterface</hardwareInterface>
            <mechanicalReduction>1</mechanicalReduction>
        </actuator>
    </transmission>
    <gazebo>
        <plugin name="wind_generator_pose_lock" filename="/home/byz/WTBinspector_ws/devel/lib/libwind_generator_pose_lock_plugin.so" />
        <plugin name="gazebo_ros_control" filename="libgazebo_ros_control.so">
            <robotNamespace>/</robotNamespace>
        </plugin>
    </gazebo>
</robot>
